Workbook

Sheet Customer Names
A1: Customer ID | B1: name
A2: Id1 | B2: Hawks, Ms. Kelly
A3: Id2 | B3: Lehner, Mr. Matthew D
A4: Id3 | B4: Lu, Mr. Phil
A5: Id4 | B5: Osborne, Ms. Kelsey
A6: Id5 | B6: Kadala, Ms. Kristyn
A7: Id6 | B7: Baker, Mr. Russell B.
A8: Id7 | B8: Macpherson, Mr. Scott
A9: Id8 | B9: Hallman, Mr. Stephen
A10: Id9 | B10: Moran, Mr. Patrick R.
A11: Id10 | B11: Benner, Ms. Brooke N.
A12: Id11 | B12: Fierro Vargas, Ms. Paola Andrea
... A2336: Id2335 | B2336: German, Mr. Aaron K

Sheet Medical Examinations (2)
A1: Customer ID | B1: BMI | C1: HBA1C | D1: Heart Issues | E1: Any Transplants | F1: Cancer history | G1: NumberOfMajorSurgeries | H1: smoker
A2: Id1 | B2: 47.41 | C2: 7.47 | D2: No | E2: No | F2: No | G2: No major surgery | H2: yes
A3: Id2 | B3: 30.36 | C3: 5.77 | D3: No | E3: No | F3: No | G3: No major surgery | H3: yes
A4: Id3 | B4: 34.485 | C4: 11.87 | D4: yes | E4: No | F4: No | G4: 2 | H4: yes
A5: Id4 | B5: 38.095 | C5: 6.05 | D5: No | E5: No | F5: No | G5: No major surgery | H5: yes
A6: Id5 | B6: 35.53 | C6: 5.45 | D6: No | E6: No | F6: No | G6: No major surgery | H6: yes
A7: Id6 | B7: 32.8 | C7: 6.59 | D7: No | E7: No | F7: No | G7: No major surgery | H7: yes
A8: Id7 | B8: 36.4 | C8: 6.07 | D8: No | E8: No | F8: No | G8: No major surgery | H8: yes
A9: Id8 | B9: 36.96 | C9: 7.93 | D9: No | E9: No | F9: No | G9: 3 | H9: yes
A10: Id9 | B10: 41.14 | C10: 9.58 | D10: yes | E10: No | F10: Yes | G10: 1 | H10: yes
A11: Id10 | B11: 38.06 | C11: 10.79 | D11: No | E11: No | F11: No | G11: No major surgery | H11: yes
A12: Id11 | B12: 37.7 | C12: 5.96 | D12: yes | E12: No | F12: No | G12: 2 | H12: yes
A13: Id12 | B13: 42.13 | C13: 11.9 | D13: No | E13: No | F13: No | G13: No major surgery | H13: yes
A14: Id13 | B14: 40.92 | C14: 8.41 | D14: No | E14: No | F14: No | G14: No major surgery | H14: yes
A15: Id14 | B15: 40.565 | C15: 7.02 | D15: No | E15: No | F15: No | G15: No major surgery | H15: yes
A16: Id15 | B16: 36.385 | C16: 7.59 | D16: yes | E16: No | F16: No | G16: 2 | H16: yes
A17: Id16 | B17: 39.9 | C17: 11.32 | D17: No | E17: No | F17: No | G17: No major surgery | H17: yes
A18: Id17 | B18: 33.8 | C18: 7.67 | D18: No | E18: No | F18: No | G18: 3 | H18: yes
A19: Id18 | B19: 36.765 | C19: 7.29 | D19: yes | E19: No | F19: Yes | G19: 1 | H19: yes
A20: Id19 | B20: 36.955 | C20: 4.72 | D20: yes | E20: No | F20: No | G20: 1 | H20: yes
A21: Id20 | B21: 42.9 | C21: 11.41 | D21: No | E21: No | F21: No | G21: No major surgery | H21: yes
A22: Id21 | B22: 36.3 | C22: 11.5 | D22: yes | E22: No | F22: No | G22: 2 | H22: yes
A23: Id22 | B23: 32.2 | C23: 6.22 | D23: yes | E23: No | F23: No | G23: 2 | H23: yes
A24: Id23 | B24: 31.3 | C24: 11.38 | D24: No | E24: No | F24: No | G24: 3 | H24: yes
A25: Id24 | B25: 41.8 | C25: 7.89 | D25: yes | E25: No | F25: No | G25: 2 | H25: yes
A26: Id25 | B26: 35.09 | C26: 4.38 | D26: yes | E26: No | F26: No | G26: 2 | H26: yes
A27: Id26 | B27: 33.88 | C27: 7.01 | D27: No | E27: No | F27: No | G27: 3 | H27: yes
A28: Id27 | B28: 30.875 | C28: 11.88 | D28: No | E28: No | F28: No | G28: No major surgery | H28: yes
A29: Id28 | B29: 36.86 | C29: 5.19 | D29: yes | E29: No | F29: Yes | G29: 1 | H29: yes
A30: Id29 | B30: 35.86 | C30: 6.74 | D30: yes | E30: No | F30: No | G30: 2 | H30: yes
A31: Id30 | B31: 37.05 | C31: 8.44 | D31: No | E31: No | F31: No | G31: No major surgery | H31: yes
A32: Id31 | B32: 43.89 | C32: 8.71 | D32: No | E32: No | F32: No | G32: No major surgery | H32: yes
A33: Id32 | B33: 42.35 | C33: 5.08 | D33: yes | E33: No | F33: No | G33: No major surgery | H33: yes
A34: Id33 | B34: 31.35 | C34: 6.86 | D34: No | E34: No | F34: No | G34: No major surgery | H34: yes
A35: Id34 | B35: 47.6 | C35: 5.95 | D35: yes | E35: No | F35: No | G35: No major surgery | H35: yes
A36: Id35 | B36: 46.2 | C36: 6.09 | D36: No | E36: No | F36: Yes | G36: 1 | H36: yes
A37: Id36 | B37: 32.015 | C37: 11.75 | D37: No | E37: No | F37: No | G37: No major surgery | H37: yes
A38: Id37 | B38: 40.565 | C38: 7.37 | D38: No | E38: No | F38: No | G38: No major surgery | H38: yes
A39: Id38 | B39: 32.45 | C39: 11.91 | D39: No | E39: No | F39: No | G39: No major surgery | H39: yes
A40: Id39 | B40: 34.96 | C40: 6.52 | D40: No | E40: No | F40: No | G40: No major surgery | H40: yes
...

Sheet Medical Examinations
A1: Customer ID | B1: BMI | C1: HBA1C | D1: Heart Issues | E1: Any Transplants | F1: Cancer history | G1: NumberOfMajorSurgeries | H1: smoker
A2: Id1 | B2: 47.41 | C2: 7.47 | D2: No | E2: No | F2: No | G2: No major surgery | H2: yes
A3: Id2 | B3: 30.36 | C3: 5.77 | D3: No | E3: No | F3: No | G3: No major surgery | H3: yes
A4: Id3 | B4: 34.485 | C4: 11.87 | D4: yes | E4: No | F4: No | G4: 2 | H4: yes
A5: Id4 | B5: 38.095 | C5: 6.05 | D5: No | E5: No | F5: No | G5: No major surgery | H5: yes
A6: Id5 | B6: 35.53 | C6: 5.45 | D6: No | E6: No | F6: No | G6: No major surgery | H6: yes
A7: Id6 | B7: 32.8 | C7: 6.59 | D7: No | E7: No | F7: No | G7: No major surgery | H7: yes
A8: Id7 | B8: 36.4 | C8: 6.07 | D8: No | E8: No | F8: No | G8: No major surgery | H8: yes
A9: Id8 | B9: 36.96 | C9: 7.93 | D9: No | E9: No | F9: No | G9: 3 | H9: yes
A10: Id9 | B10: 41.14 | C10: 9.58 | D10: yes | E10: No | F10: Yes | G10: 1 | H10: yes
A11: Id10 | B11: 38.06 | C11: 10.79 | D11: No | E11: No | F11: No | G11: No major surgery | H11: yes
A12: Id11 | B12: 37.7 | C12: 5.96 | D12: yes | E12: No | F12: No | G12: 2 | H12: yes
A13: Id12 | B13: 42.13 | C13: 11.9 | D13: No | E13: No | F13: No | G13: No major surgery | H13: yes
A14: Id13 | B14: 40.92 | C14: 8.41 | D14: No | E14: No | F14: No | G14: No major surgery | H14: yes
A15: Id14 | B15: 40.565 | C15: 7.02 | D15: No | E15: No | F15: No | G15: No major surgery | H15: yes
A16: Id15 | B16: 36.385 | C16: 7.59 | D16: yes | E16: No | F16: No | G16: 2 | H16: yes
A17: Id16 | B17: 39.9 | C17: 11.32 | D17: No | E17: No | F17: No | G17: No major surgery | H17: yes
A18: Id17 | B18: 33.8 | C18: 7.67 | D18: No | E18: No | F18: No | G18: 3 | H18: yes
A19: Id18 | B19: 36.765 | C19: 7.29 | D19: yes | E19: No | F19: Yes | G19: 1 | H19: yes
A20: Id19 | B20: 36.955 | C20: 4.72 | D20: yes | E20: No | F20: No | G20: 1 | H20: yes
A21: Id20 | B21: 42.9 | C21: 11.41 | D21: No | E21: No | F21: No | G21: No major surgery | H21: yes
A22: Id21 | B22: 36.3 | C22: 11.5 | D22: yes | E22: No | F22: No | G22: 2 | H22: yes
A23: Id22 | B23: 32.2 | C23: 6.22 | D23: yes | E23: No | F23: No | G23: 2 | H23: yes
A24: Id23 | B24: 31.3 | C24: 11.38 | D24: No | E24: No | F24: No | G24: 3 | H24: yes
A25: Id24 | B25: 41.8 | C25: 7.89 | D25: yes | E25: No | F25: No | G25: 2 | H25: yes
A26: Id25 | B26: 35.09 | C26: 4.38 | D26: yes | E26: No | F26: No | G26: 2 | H26: yes
A27: Id26 | B27: 33.88 | C27: 7.01 | D27: No | E27: No | F27: No | G27: 3 | H27: yes
A28: Id27 | B28: 30.875 | C28: 11.88 | D28: No | E28: No | F28: No | G28: No major surgery | H28: yes
A29: Id28 | B29: 36.86 | C29: 5.19 | D29: yes | E29: No | F29: Yes | G29: 1 | H29: yes
A30: Id29 | B30: 35.86 | C30: 6.74 | D30: yes | E30: No | F30: No | G30: 2 | H30: yes
A31: Id30 | B31: 37.05 | C31: 8.44 | D31: No | E31: No | F31: No | G31: No major surgery | H31: yes
A32: Id31 | B32: 43.89 | C32: 8.71 | D32: No | E32: No | F32: No | G32: No major surgery | H32: yes
A33: Id32 | B33: 42.35 | C33: 5.08 | D33: yes | E33: No | F33: No | G33: No major surgery | H33: yes
A34: Id33 | B34: 31.35 | C34: 6.86 | D34: No | E34: No | F34: No | G34: No major surgery | H34: yes
A35: Id34 | B35: 47.6 | C35: 5.95 | D35: yes | E35: No | F35: No | G35: No major surgery | H35: yes
A36: Id35 | B36: 46.2 | C36: 6.09 | D36: No | E36: No | F36: Yes | G36: 1 | H36: yes
A37: Id36 | B37: 32.015 | C37: 11.75 | D37: No | E37: No | F37: No | G37: No major surgery | H37: yes
A38: Id37 | B38: 40.565 | C38: 7.37 | D38: No | E38: No | F38: No | G38: No major surgery | H38: yes
A39: Id38 | B39: 32.45 | C39: 11.91 | D39: No | E39: No | F39: No | G39: No major surgery | H39: yes
A40: Id39 | B40: 34.96 | C40: 6.52 | D40: No | E40: No | F40: No | G40: No major surgery | H40: yes
...

Sheet Hospitalisation Details
A1: Customer ID | B1: year | C1: month | D1: date | E1: children | F1: charges | G1: Hospital tier | H1: City tier | I1: State ID
A2: Id2335 | B2: 1992 | C2: Jul | D2: 9 | E2: 0 | F2: 563.84 | G2: tier - 2 | H2: tier - 3 | I2: R1013
A3: Id2334 | B3: 1992 | C3: Nov | D3: 30 | E3: 0 | F3: 570.62 | G3: tier - 2 | H3: tier - 1 | I3: R1013
A4: Id2333 | B4: 1993 | C4: Jun | D4: 30 | E4: 0 | F4: 600 | G4: tier - 2 | H4: tier - 1 | I4: R1013
A5: Id2332 | B5: 1992 | C5: Sep | D5: 13 | E5: 0 | F5: 604.54 | G5: tier - 3 | H5: tier - 3 | I5: R1013
A6: Id2331 | B6: 1998 | C6: Jul | D6: 27 | E6: 0 | F6: 637.26 | G6: tier - 3 | H6: tier - 3 | I6: R1013
A7: Id2330 | B7: 2001 | C7: Nov | D7: 20 | E7: 0 | F7: 646.14 | G7: tier - 3 | H7: tier - 3 | I7: R1012
A8: Id2329 | B8: 1993 | C8: Jun | D8: 1 | E8: 0 | F8: 650 | G8: tier - 3 | H8: tier - 3 | I8: R1013
A9: Id2328 | B9: 1995 | C9: Jul | D9: 4 | E9: 0 | F9: 650 | G9: tier - 3 | H9: tier - 3 | I9: R1013
A10: Id2327 | B10: 2002 | C10: Nov | D10: 29 | E10: 0 | F10: 668 | G10: tier - 3 | H10: tier - 2 | I10: R1012
A11: Id2326 | B11: 1997 | C11: Nov | D11: 9 | E11: 0 | F11: 670 | G11: tier - 3 | H11: tier - 3 | I11: R1013
A12: Id2325 | B12: 2001 | C12: Sep | D12: 12 | E12: 0 | F12: 687.54 | G12: tier - 3 | H12: tier - 2 | I12: R1013
A13: Id2324 | B13: 1999 | C13: Dec | D13: 26 | E13: 0 | F13: 700 | G13: ? | H13: tier - 3 | I13: R1013
... A1050: Id1290 | B1050: 1977 | C1050: Jul | D1050: 26 | E1050: 2 | F1050: 8527.53 | G1050: tier - 2 | H1050: tier - 2 | I1050: R1013
A1051: Id1289 | B1051: ? | C1051: Jul | D1051: 24 | E1051: 0 | F1051: 8534.67 | G1051: tier - 2 | H1051: tier - 3 | I1051: R1024
A1052: Id1288 | B1052: 1981 | C1052: Dec | D1052: 27 | E1052: 3 | F1052: 8538.29 | G1052: tier - 2 | H1052: tier - 3 | I1052: R1024
A1053: Id1287 | B1053: 1975 | C1053: Nov | D1053: 6 | E1053: 1 | F1053: 8539.67 | G1053: tier - 2 | H1053: tier - 3 | I1053: R1011
A1054: Id1286 | B1054: ? | C1054: Dec | D1054: 12 | E1054: 1 | F1054: 8547.69 | G1054: tier - 2 | H1054: tier - 1 | I1054: R1013
A1055: Id1285 | B1055: 1975 | C1055: Aug | D1055: 6 | E1055: 1 | F1055: 8551.35 | G1055: tier - 2 | H1055: tier - 2 | I1055: R1011
A1056: Id1284 | B1056: 1975 | C1056: Aug | D1056: 21 | E1056: 1 | F1056: 8556.91 | G1056: tier - 2 | H1056: tier - 1 | I1056: R1011
A1057: Id1283 | B1057: 1988 | C1057: Sep | D1057: 21 | E1057: 3 | F1057: 8567.25 | G1057: tier - 2 | H1057: tier - 1 | I1057: R1012
A1058: Id1282 | B1058: 1975 | C1058: Sep | D1058: 26 | E1058: 1 | F1058: 8569.86 | G1058: tier - 2 | H1058: tier - 3 | I1058: R1013
A1059: Id1281 | B1059: 1982 | C1059: Dec | D1059: 6 | E1059: 3 | F1059: 8572.04 | G1059: tier - 2 | H1059: tier - 2 | I1059: R1021
A1060: Id1280 | B1060: 1987 | C1060: Nov | D1060: 11 | E1060: 3 | F1060: 8573.3 | G1060: tier - 2 | H1060: tier - 2 | I1060: R1021
A1061: Id1279 | B1061: 1983 | C1061: Dec | D1061: 30 | E1061: 5 | F1061: 8582.3 | G1061: tier - 2 | H1061: tier - 1 | I1061: R1013
A1062: Id1278 | B1062: 1983 | C1062: Jul | D1062: 25 | E1062: 5 | F1062: 8596.83 | G1062: tier - 2 | H1062: tier - 3 | I1062: R1013
A1063: Id1277 | B1063: 1973 | C1063: Jul | D1063: 11 | E1063: 0 | F1063: 8601.33 | G1063: tier - 2 | H1063: tier - 1 | I1063: R1013
A1064: Id1276 | B1064: 1977 | C1064: Sep | D1064: 24 | E1064: 2 | F1064: 8603.82 | G1064: tier - 2 | H1064: tier - 1 | I1064: R1019
A1065: Id1275 | B1065: 1977 | C1065: Nov | D1065: 12 | E1065: 2 | F1065: 8604.48 | G1065: tier - 3 | H1065: tier - 2 | I1065: R1016
A1066: Id1274 | B1066: 1977 | C1066: Oct | D1066: 15 | E1066: 3 | F1066: 8605.36 | G1066: tier - 2 | H1066: tier - 2 | I1066: R1013
... A2344: Id1 | B2344: 1968 | C2344: Oct | D2344: 12 | E2344: 0 | F2344: 63770.43 | G2344: tier - 1 | H2344: tier - 3 | I2344: R1013

Sheet solution datacleaning
A1: Check for the number of missing values marked with '?' in each column of the “Medical" Examinations” Table and "Hospitalization Details" Table. Examinations” Table and "Hospitalization Details" Table.
A3: Column1 | B3: Column2 | C3: Column3 | D3: Column4 | E3: Column5 | F3: Column6
A4: Medical Examinations | D4: Hospitalization Details
A6: Customer ID | B6: =COUNTIF('Medical Examinations'!A:A,"?") -> 0 | D6: Customer ID | E6: =COUNTIF('Hospitalisation Details'!A:A,"?") -> 6
A7: BMI | B7: =COUNTIF('Medical Examinations'!B:B,"?") -> 0 | D7: year | E7: =COUNTIF('Hospitalisation Details'!B:B,"?") -> 2
A8: HBA1C | B8: =COUNTIF('Medical Examinations'!D:D,"?") -> 0 | D8: month | E8: =COUNTIF('Hospitalisation Details'!C:C,"?") -> 3
A9: Heart Issues | B9: =COUNTIF('Medical Examinations'!E:E,"?") -> 0 | D9: date | E9: =COUNTIF('Hospitalisation Details'!D:D,"?") -> 0
A10: Any Transplants | B10: =COUNTIF('Medical Examinations'!E:E,"?") -> 0 | D10: children | E10: =COUNTIF('Hospitalisation Details'!E:E,"?") -> 0
A11: Cancer history | B11: =COUNTIF('Medical Examinations'!F:F,"?") -> 0 | D11: charges | E11: =COUNTIF('Hospitalisation Details'!F:F,"?") -> 0
A12: NumberOfMajorSurgeries | B12: =COUNTIF('Medical Examinations'!G:G,"?") -> 0 | D12: hospital tier | E12: =COUNTIF('Hospitalisation Details'!G:G,"?") -> 1
A13: smoker | B13: =COUNTIF('Medical Examinations'!H:H,"?") -> 2 | D13: city tier | E13: =COUNTIF('Hospitalisation Details'!H:H,"?") -> 1
D14: state ID | E14: =COUNTIF('Hospitalisation Details'!I:I,"?") -> 2
A15: Total | B15: =SUM(B6:B13) -> 2 | D15: Total | E15: =SUM(E6:E14) -> 15
A16: Grand Total | B16: =COUNTIF('Medical Examinations'!A:H,"?")+COUNTIF('Hospitalisation Details'!A:I,"?") -> 17
A18: Fill in the missing values of ‘month’ with Sep and ‘year’ with its average rounded to the nearest integer.
A19: =ROUND(AVERAGEIF('Hospitalisation Details'!B:B,"<>?"),0) -> 1983

Sheet solution datacleaning2
A1: Customer ID | B1: year | C1: month | D1: date | E1: children | F1: charges | G1: Hospital tier | H1: City tier | I1: State ID | O1: Customer ID | P1: BMI | Q1: HBA1C | R1: Heart Issues | S1: Any Transplants | T1: Cancer history | U1: NumberOfMajorSurgeries | V1: smoker
A2: Id2335 | B2: 1992 | C2: Jul | D2: 9 | E2: 0 | F2: 563.84 | G2: tier - 2 | H2: tier - 3 | I2: R1013 | L2: Hospital tier-1 | M2: =COUNTIF('Hospitalisation Details'!G:G,"tier - 1") -> 309 | O2: Id1 | P2: 47.41 | Q2: 7.47 | R2: No | S2: No | T2: No | U2: No major surgery | V2: yes
A3: Id2334 | B3: 1992 | C3: Nov | D3: 30 | E3: 0 | F3: 570.62 | G3: tier - 2 | H3: tier - 1 | I3: R1013 | L3: Hospital tier-2 | M3: =COUNTIF('Hospitalisation Details'!G:G,"tier - 2") -> 1339 | O3: Id2 | P3: 30.36 | Q3: 5.77 | R3: No | S3: No | T3: No | U3: No major surgery | V3: yes
A4: Id2333 | B4: 1993 | C4: Jun | D4: 30 | E4: 0 | F4: 600 | G4: tier - 2 | H4: tier - 1 | I4: R1013 | L4: Hospital tier-3 | M4: =COUNTIF('Hospitalisation Details'!G:G,"tier - 3") -> 694 | O4: Id3 | P4: 34.485 | Q4: 11.87 | R4: yes | S4: No | T4: No | U4: 2 | V4: yes
A5: Id2332 | B5: 1992 | C5: Sep | D5: 13 | E5: 0 | F5: 604.54 | G5: tier - 3 | H5: tier - 3 | I5: R1013 | L5: City tier-1 | M5: =COUNTIF('Hospitalisation Details'!H:H,"tier - 1") -> 734 | O5: Id4 | P5: 38.095 | Q5: 6.05 | R5: No | S5: No | T5: No | U5: No major surgery | V5: yes
A6: Id2331 | B6: 1998 | C6: Jul | D6: 27 | E6: 0 | F6: 637.26 | G6: tier - 3 | H6: tier - 3 | I6: R1013 | L6: City tier-2 | M6: =COUNTIF('Hospitalisation Details'!H:H,"tier - 2") -> 812 | O6: Id5 | P6: 35.53 | Q6: 5.45 | R6: No | S6: No | T6: No | U6: No major surgery | V6: yes
A7: Id2330 | B7: 2001 | C7: Nov | D7: 20 | E7: 0 | F7: 646.14 | G7: tier - 3 | H7: tier - 3 | I7: R1012 | L7: City tier-3 | M7: =COUNTIF('Hospitalisation Details'!H:H,"tier - 3") -> 796 | O7: Id6 | P7: 32.8 | Q7: 6.59 | R7: No | S7: No | T7: No | U7: No major surgery | V7: yes
A8: Id2329 | B8: 1993 | C8: Jun | D8: 1 | E8: 0 | F8: 650 | G8: tier - 3 | H8: tier - 3 | I8: R1013 | L8: Year | M8: =ROUND(AVERAGEIF('Hospitalisation Details'!B:B,"<>?"),0) -> 1983 | O8: Id7 | P8: 36.4 | Q8: 6.07 | R8: No | S8: No | T8: No | U8: No major surgery | V8: yes
A9: Id2328 | B9: 1995 | C9: Jul | D9: 4 | E9: 0 | F9: 650 | G9: tier - 3 | H9: tier - 3 | I9: R1013 | L9: yes | M9: =COUNTIF(V:V,"yes") -> 488 | O9: Id8 | P9: 36.96 | Q9: 7.93 | R9: No | S9: No | T9: No | U9: 3 | V9: yes
A10: Id2327 | B10: 2002 | C10: Nov | D10: 29 | E10: 0 | F10: 668 | G10: tier - 3 | H10: tier - 2 | I10: R1012 | L10: No | M10: =COUNTIF(V:V,"No") -> 1845 | O10: Id9 | P10: 41.14 | Q10: 9.58 | R10: yes | S10: No | T10: Yes | U10: 1 | V10: yes
A11: Id2326 | B11: 1997 | C11: Nov | D11: 9 | E11: 0 | F11: 670 | G11: tier - 3 | H11: tier - 3 | I11: R1013 | L11: Month | M11: =COUNTIF('Hospitalisation Details'!C:C,"~?") -> 3 | O11: Id10 | P11: 38.06 | Q11: 10.79 | R11: No | S11: No | T11: No | U11: No major surgery | V11: yes
A12: Id2325 | B12: 2001 | C12: Sep | D12: 12 | E12: 0 | F12: 687.54 | G12: tier - 3 | H12: tier - 2 | I12: R1013 | O12: Id11 | P12: 37.7 | Q12: 5.96 | R12: yes | S12: No | T12: No | U12: 2 | V12: yes
A13: Id2324 | B13: 1999 | C13: Dec | D13: 26 | E13: 0 | F13: 700 | G13: tier - 2 | H13: tier - 3 | I13: R1013 | O13: Id12 | P13: 42.13 | Q13: 11.9 | R13: No | S13: No | T13: No | U13: No major surgery | V13: yes
A14: Id2323 | B14: 1999 | C14: Dec | D14: 14 | E14: 0 | F14: 722.99 | G14: tier - 3 | H14: tier - 1 | I14: R1013 | O14: Id13 | P14: 40.92 | Q14: 8.41 | R14: No | S14: No | T14: No | U14: No major surgery | V14: yes
A15: Id2322 | B15: 2002 | C15: Sep | D15: 19 | E15: 0 | F15: 750 | G15: tier - 3 | H15: tier - 1 | I15: R1012 | O15: Id14 | P15: 40.565 | Q15: 7.02 | R15: No | S15: No | T15: No | U15: No major surgery | V15: yes
A16: Id2321 | B16: 1993 | C16: Aug | D16: 9 | E16: 0 | F16: 760 | G16: tier - 3 | H16: tier - 1 | I16: R1013 | O16: Id15 | P16: 36.385 | Q16: 7.59 | R16: yes | S16: No | T16: No | U16: 2 | V16: yes
A17: Id2320 | B17: 1996 | C17: Oct | D17: 22 | E17: 0 | F17: 760 | G17: tier - 3 | H17: tier - 3 | I17: R1013 | O17: Id16 | P17: 39.9 | Q17: 11.32 | R17: No | S17: No | T17: No | U17: No major surgery | V17: yes
A18: Id2319 | B18: 1993 | C18: Jun | D18: 28 | E18: 0 | F18: 770 | G18: tier - 3 | H18: tier - 3 | I18: R1013 | O18: Id17 | P18: 33.8 | Q18: 7.67 | R18: No | S18: No | T18: No | U18: 3 | V18: yes
A19: Id2318 | B19: 1996 | C19: Sep | D19: 18 | E19: 0 | F19: 770.38 | G19: tier - 3 | H19: tier - 2 | I19: R1012 | O19: Id18 | P19: 36.765 | Q19: 7.29 | R19: yes | S19: No | T19: Yes | U19: 1 | V19: yes
A20: Id2317 | B20: 1995 | C20: Dec | D20: 7 | E20: 0 | F20: 773.54 | G20: tier - 3 | H20: tier - 2 | I20: R1013 | O20: Id19 | P20: 36.955 | Q20: 4.72 | R20: yes | S20: No | T20: No | U20: 1 | V20: yes
A21: Id2316 | B21: 2004 | C21: Oct | D21: 7 | E21: 0 | F21: 830.52 | G21: tier - 3 | H21: tier - 2 | I21: R1011 | O21: Id20 | P21: 42.9 | Q21: 11.41 | R21: No | S21: No | T21: No | U21: No major surgery | V21: yes
A22: Id2315 | B22: 2000 | C22: Nov | D22: 18 | E22: 0 | F22: 865.41 | G22: tier - 3 | H22: tier - 1 | I22: R1013 | O22: Id21 | P22: 36.3 | Q22: 11.5 | R22: yes | S22: No | T22: No | U22: 2 | V22: yes
A23: Id2314 | B23: 1993 | C23: Nov | D23: 27 | E23: 0 | F23: 896.21 | G23: tier - 3 | H23: tier - 1 | I23: R1013 | O23: Id22 | P23: 32.2 | Q23: 6.22 | R23: yes | S23: No | T23: No | U23: 2 | V23: yes
A24: Id2313 | B24: 1994 | C24: Oct | D24: 30 | E24: 0 | F24: 915.07 | G24: tier - 3 | H24: tier - 1 | I24: R1013 | O24: Id23 | P24: 31.3 | Q24: 11.38 | R24: No | S24: No | T24: No | U24: 3 | V24: yes
A25: Id2312 | B25: 1995 | C25: Oct | D25: 28 | E25: 0 | F25: 928.59 | G25: tier - 3 | H25: tier - 1 | I25: R1013 | O25: Id24 | P25: 41.8 | Q25: 7.89 | R25: yes | S25: No | T25: No | U25: 2 | V25: yes
A26: Id2311 | B26: 2001 | C26: Aug | D26: 19 | E26: 0 | F26: 964.71 | G26: tier - 3 | H26: tier - 2 | I26: R1013 | O26: Id25 | P26: 35.09 | Q26: 4.38 | R26: yes | S26: No | T26: No | U26: 2 | V26: yes
A27: Id2310 | B27: 1994 | C27: Nov | D27: 22 | E27: 0 | F27: 1006.65 | G27: tier - 3 | H27: tier - 2 | I27: R1013 | O27: Id26 | P27: 33.88 | Q27: 7.01 | R27: No | S27: No | T27: No | U27: 3 | V27: yes
A28: Id2309 | B28: 2000 | C28: Oct | D28: 9 | E28: 0 | F28: 1012 | G28: tier - 3 | H28: tier - 2 | I28: R1013 | O28: Id27 | P28: 30.875 | Q28: 11.88 | R28: No | S28: No | T28: No | U28: No major surgery | V28: yes
A29: Id2308 | B29: 1999 | C29: Aug | D29: 5 | E29: 0 | F29: 1019 | G29: tier - 3 | H29: tier - 2 | I29: R1013 | O29: Id28 | P29: 36.86 | Q29: 5.19 | R29: yes | S29: No | T29: Yes | U29: 1 | V29: yes
A30: Id2307 | B30: 1995 | C30: Oct | D30: 5 | E30: 0 | F30: 1033.74 | G30: tier - 3 | H30: tier - 1 | I30: R1013 | O30: Id29 | P30: 35.86 | Q30: 6.74 | R30: yes | S30: No | T30: No | U30: 2 | V30: yes
A31: Id2306 | B31: 1994 | C31: Nov | D31: 17 | E31: 0 | F31: 1044 | G31: tier - 3 | H31: tier - 2 | I31: R1013 | O31: Id30 | P31: 37.05 | Q31: 8.44 | R31: No | S31: No | T31: No | U31: No major surgery | V31: yes
A32: Id2305 | B32: 2002 | C32: Jul | D32: 20 | E32: 0 | F32: 1047 | G32: tier - 3 | H32: tier - 1 | I32: R1013 | O32: Id31 | P32: 43.89 | Q32: 8.71 | R32: No | S32: No | T32: No | U32: No major surgery | V32: yes
A33: Id2304 | B33: 2002 | C33: Jul | D33: 1 | E33: 0 | F33: 1049 | G33: tier - 3 | H33: tier - 2 | I33: R1012 | O33: Id32 | P33: 42.35 | Q33: 5.08 | R33: yes | S33: No | T33: No | U33: No major surgery | V33: yes
A34: Id2303 | B34: 1995 | C34: Jun | D34: 1 | E34: 0 | F34: 1056 | G34: tier - 3 | H34: tier - 2 | I34: R1013 | O34: Id33 | P34: 31.35 | Q34: 6.86 | R34: No | S34: No | T34: No | U34: No major surgery | V34: yes
A35: Id2302 | B35: 1993 | C35: Sep | D35: 28 | E35: 0 | F35: 1068 | G35: tier - 3 | H35: tier - 1 | I35: R1013 | O35: Id34 | P35: 47.6 | Q35: 5.95 | R35: yes | S35: No | T35: No | U35: No major surgery | V35: yes
A36: Id2301 | B36: 2004 | C36: Aug | D36: 24 | E36: 0 | F36: 1070 | G36: tier - 3 | H36: tier - 3 | I36: R1013 | O36: Id35 | P36: 46.2 | Q36: 6.09 | R36: No | S36: No | T36: Yes | U36: 1 | V36: yes
A37: Id2300 | B37: 1997 | C37: Aug | D37: 13 | E37: 0 | F37: 1071 | G37: tier - 3 | H37: tier - 3 | I37: R1013 | O37: Id36 | P37: 32.015 | Q37: 11.75 | R37: No | S37: No | T37: No | U37: No major surgery | V37: yes
A38: Id2299 | B38: 1998 | C38: Dec | D38: 26 | E38: 0 | F38: 1082 | G38: tier - 3 | H38: tier - 2 | I38: R1013 | O38: Id37 | P38: 40.565 | Q38: 7.37 | R38: No | S38: No | T38: No | U38: No major surgery | V38: yes
A39: Id2298 | B39: 2002 | C39: Aug | D39: 13 | E39: 0 | F39: 1086 | G39: tier - 3 | H39: tier - 3 | I39: R1013 | O39: Id38 | P39: 32.45 | Q39: 11.91 | R39: No | S39: No | T39: No | U39: No major surgery | V39: yes
A40: Id2297 | B40: 2004 | C40: Nov | D40: 12 | E40: 0 | F40: 1121.87 | G40: tier - 3 | H40: tier - 1 | I40: R1013 | O40: Id39 | P40: 34.96 | Q40: 6.52 | R40: No | S40: No | T40: No | U40: No major surgery | V40: yes
...

Sheet data transform solution
A1: Customer ID | B1: Title | C1: First Name | D1: Last Name
A2: Id1 | B2: Ms | C2: Kelly | D2: Hawks
A3: Id2 | B3: Mr | C3: Matthew D | D3: Lehner
A4: Id3 | B4: Mr | C4: Phil | D4: Lu
A5: Id4 | B5: Ms | C5: Kelsey | D5: Osborne
A6: Id5 | B6: Ms | C6: Kristyn | D6: Kadala
A7: Id6 | B7: Mr | C7: Russell B | D7: Baker
A8: Id7 | B8: Mr | C8: Scott | D8: Macpherson
A9: Id8 | B9: Mr | C9: Stephen | D9: Hallman
A10: Id9 | B10: Mr | C10: Patrick R | D10: Moran
A11: Id10 | B11: Ms | C11: Brooke N | D11: Benner
A12: Id11 | B12: Ms | C12: Paola Andrea | D12: Fierro Vargas
... A2336: Id2335 | B2336: Mr | C2336: Aaron K | D2336: German

Sheet Medical Examinations Datatransf
A1: Customer ID | B1: BMI | C1: HBA1C | D1: Heart Issues | E1: Any Transplants | F1: Cancer history | G1: NumberOfMajorSurgeries | H1: smoker | I1: Weight Status | J1: Diabetes Status
A2: Id1 | B2: 47.41 | C2: 7.47 | D2: No | E2: No | F2: No | G2: 0 | H2: Yes | I2: Obesity | J2: Diabetes
A3: Id2 | B3: 30.36 | C3: 5.77 | D3: No | E3: No | F3: No | G3: 0 | H3: Yes | I3: Obesity | J3: Prediabetes
A4: Id3 | B4: 34.485 | C4: 11.87 | D4: Yes | E4: No | F4: No | G4: 2 | H4: Yes | I4: Obesity | J4: Diabetes
A5: Id4 | B5: 38.095 | C5: 6.05 | D5: No | E5: No | F5: No | G5: 0 | H5: Yes | I5: Obesity | J5: Prediabetes
A6: Id5 | B6: 35.53 | C6: 5.45 | D6: No | E6: No | F6: No | G6: 0 | H6: Yes | I6: Obesity | J6: Normal
A7: Id6 | B7: 32.8 | C7: 6.59 | D7: No | E7: No | F7: No | G7: 0 | H7: Yes | I7: Obesity | J7: Diabetes
A8: Id7 | B8: 36.4 | C8: 6.07 | D8: No | E8: No | F8: No | G8: 0 | H8: Yes | I8: Obesity | J8: Prediabetes
A9: Id8 | B9: 36.96 | C9: 7.93 | D9: No | E9: No | F9: No | G9: 3 | H9: Yes | I9: Obesity | J9: Diabetes
A10: Id9 | B10: 41.14 | C10: 9.58 | D10: Yes | E10: No | F10: Yes | G10: 1 | H10: Yes | I10: Obesity | J10: Diabetes
A11: Id10 | B11: 38.06 | C11: 10.79 | D11: No | E11: No | F11: No | G11: 0 | H11: Yes | I11: Obesity | J11: Diabetes
A12: Id11 | B12: 37.7 | C12: 5.96 | D12: Yes | E12: No | F12: No | G12: 2 | H12: Yes | I12: Obesity | J12: Prediabetes
A13: Id12 | B13: 42.13 | C13: 11.9 | D13: No | E13: No | F13: No | G13: 0 | H13: Yes | I13: Obesity | J13: Diabetes
... A2336: Id2335 | B2336: 17.58 | C2336: 4.51 | D2336: No | E2336: No | F2336: No | G2336: 1 | H2336: No | I2336: Underweight | J2336: Normal

Sheet Hospital Details Cleaned
A1: Customer ID | B1: year | C1: month | D1: date | E1: children | F1: charges | G1: Hospital tier | H1: City tier | I1: State ID
A2: Id2335 | B2: 1992 | C2: Jul | D2: 9 | E2: 0 | F2: 563.84 | G2: tier - 2 | H2: tier - 3 | I2: R1013
A3: Id2334 | B3: 1992 | C3: Nov | D3: 30 | E3: 0 | F3: 570.62 | G3: tier - 2 | H3: tier - 1 | I3: R1013
A4: Id2333 | B4: 1993 | C4: Jun | D4: 30 | E4: 0 | F4: 600 | G4: tier - 2 | H4: tier - 1 | I4: R1013
A5: Id2332 | B5: 1992 | C5: Sep | D5: 13 | E5: 0 | F5: 604.54 | G5: tier - 3 | H5: tier - 3 | I5: R1013
A6: Id2331 | B6: 1998 | C6: Jul | D6: 27 | E6: 0 | F6: 637.26 | G6: tier - 3 | H6: tier - 3 | I6: R1013
A7: Id2330 | B7: 2001 | C7: Nov | D7: 20 | E7: 0 | F7: 646.14 | G7: tier - 3 | H7: tier - 3 | I7: R1012
A8: Id2329 | B8: 1993 | C8: Jun | D8: 1 | E8: 0 | F8: 650 | G8: tier - 3 | H8: tier - 3 | I8: R1013
A9: Id2328 | B9: 1995 | C9: Jul | D9: 4 | E9: 0 | F9: 650 | G9: tier - 3 | H9: tier - 3 | I9: R1013
A10: Id2327 | B10: 2002 | C10: Nov | D10: 29 | E10: 0 | F10: 668 | G10: tier - 3 | H10: tier - 2 | I10: R1012
A11: Id2326 | B11: 1997 | C11: Nov | D11: 9 | E11: 0 | F11: 670 | G11: tier - 3 | H11: tier - 3 | I11: R1013
A12: Id2325 | B12: 2001 | C12: Sep | D12: 12 | E12: 0 | F12: 687.54 | G12: tier - 3 | H12: tier - 2 | I12: R1013
A13: Id2324 | B13: 1999 | C13: Dec | D13: 26 | E13: 0 | F13: 700 | G13: tier - 2 | H13: tier - 3 | I13: R1013
... A2344: Id1 | B2344: 1968 | C2344: Oct | D2344: 12 | E2344: 0 | F2344: 63770.43 | G2344: tier - 1 | H2344: tier - 3 | I2344: R1013

Sheet Hospital Details Cleaned (2)
A1: Customer ID | B1: Date of Birth | C1: children | D1: charges | E1: Hospital tier | F1: City tier | G1: State ID | H1: Age
A2: Id2335 | B2: 33794 | C2: 0 | D2: 563.84 | E2: tier - 2 | F2: tier - 3 | G2: R1013 | H2: 30
A3: Id2334 | B3: 33938 | C3: 0 | D3: 570.62 | E3: tier - 2 | F3: tier - 1 | G3: R1013 | H3: 30
A4: Id2333 | B4: 34150 | C4: 0 | D4: 600 | E4: tier - 2 | F4: tier - 1 | G4: R1013 | H4: 29
A5: Id2332 | B5: 33860 | C5: 0 | D5: 604.54 | E5: tier - 3 | F5: tier - 3 | G5: R1013 | H5: 30
A6: Id2331 | B6: 36003 | C6: 0 | D6: 637.26 | E6: tier - 3 | F6: tier - 3 | G6: R1013 | H6: 24
A7: Id2330 | B7: 37215 | C7: 0 | D7: 646.14 | E7: tier - 3 | F7: tier - 3 | G7: R1012 | H7: 21
A8: Id2329 | B8: 34121 | C8: 0 | D8: 650 | E8: tier - 3 | F8: tier - 3 | G8: R1013 | H8: 30
A9: Id2328 | B9: 34884 | C9: 0 | D9: 650 | E9: tier - 3 | F9: tier - 3 | G9: R1013 | H9: 27
A10: Id2327 | B10: 37589 | C10: 0 | D10: 668 | E10: tier - 3 | F10: tier - 2 | G10: R1012 | H10: 20
A11: Id2326 | B11: 35743 | C11: 0 | D11: 670 | E11: tier - 3 | F11: tier - 3 | G11: R1013 | H11: 25
A12: Id2325 | B12: 37146 | C12: 0 | D12: 687.54 | E12: tier - 3 | F12: tier - 2 | G12: R1013 | H12: 21
A13: Id2324 | B13: 36520 | C13: 0 | D13: 700 | E13: tier - 2 | F13: tier - 3 | G13: R1013 | H13: 23
... A2344: Id1 | B2344: 25123 | C2344: 0 | D2344: 63770.43 | E2344: tier - 1 | F2344: tier - 3 | G2344: R1013 | H2344: 54
